Workbook

Sheet Instructions
A1: MS Excel Practical Exam
A2: Total Questions: 30
A3: Difficulty Level: Medium
A4: Syllabus: Formulas, Logical Functions, Lookups, INDEX-MATCH, Pivot Tables & Charts, Data Analysis
A5: Attempt all questions using appropriate Excel tools/functions.

Sheet Sales_Data
A1: Order_ID | B1: Region | C1: Salesperson | D1: Product | E1: Quantity | F1: Unit_Price | G1: Sales_Date | H1: Total Sales | I1: GST Amount | J1: Total Sales
A2: 301 | B2: North | C2: Amit | D2: Laptop | E2: 2 | F2: 45000 | G2: 05-01-2025 | H2: =E2*F2 -> 90000 | I2: =VLOOKUP(D2,Product_Master!$A$1:$C$4,3,0)/100 -> 0.18 | J2: =H2*I2 -> 16200
A3: 302 | B3: South | C3: Riya | D3: Mobile | E3: 5 | F3: 15000 | G3: 07-01-2025 | H3: =E3*F3 -> 75000 | I3: =VLOOKUP(D3,Product_Master!$A$1:$C$4,3,0)/100 -> 0.12 | J3: =H3*I3 -> 9000 | K3: `
A4: 303 | B4: East | C4: Kunal | D4: Tablet | E4: 3 | F4: 18000 | G4: 10-01-2025 | H4: =E4*F4 -> 54000 | I4: =VLOOKUP(D4,Product_Master!$A$1:$C$4,3,0)/100 -> 0.12 | J4: =H4*I4 -> 6480
A5: 304 | B5: West | C5: Neha | D5: Laptop | E5: 1 | F5: 45000 | G5: 12-01-2025 | H5: =E5*F5 -> 45000 | I5: =VLOOKUP(D5,Product_Master!$A$1:$C$4,3,0)/100 -> 0.18 | J5: =H5*I5 -> 8100
A6: 305 | B6: North | C6: Amit | D6: Mobile | E6: 4 | F6: 15000 | G6: 15-01-2025 | H6: =E6*F6 -> 60000 | I6: =VLOOKUP(D6,Product_Master!$A$1:$C$4,3,0)/100 -> 0.12 | J6: =H6*I6 -> 7200
A7: 306 | B7: South | C7: Riya | D7: Laptop | E7: 2 | F7: 45000 | G7: 18-01-2025 | H7: =E7*F7 -> 90000 | I7: =VLOOKUP(D7,Product_Master!$A$1:$C$4,3,0)/100 -> 0.18 | J7: =H7*I7 -> 16200
E8: =COUNTA(E2:E7) -> 6 | I8: Grand Total | J8: =SUM(J2:J7) -> 63180

Sheet Product_Master
A1: Product | B1: Category | C1: GST_%
A2: Laptop | B2: Electronics | C2: 18
A3: Mobile | B3: Electronics | C3: 12
A4: Tablet | B4: Electronics | C4: 12

Sheet Student_Marks
A1: Student_ID | B1: Name | C1: Maths | D1: Statistics | E1: Excel | F1: Attendance_%
A2: 1 | B2: Rahul | C2: 78 | D2: 82 | E2: 85 | F2: 92
A3: 2 | B3: Sneha | C3: 88 | D3: 91 | E3: 90 | F3: 96
A4: 3 | B4: Arjun | C4: 65 | D4: 70 | E4: 72 | F4: 85
A5: 4 | B5: Pooja | C5: 92 | D5: 89 | E5: 94 | F5: 98
A6: 5 | B6: Vikas | C6: 55 | D6: 60 | E6: 58 | F6: 80

Sheet Questions
A1: 1. Calculate Total Sales for each order (Quantity × Unit_Price). | J1: 2
A2: 2. Calculate GST Amount using VLOOKUP from Product_Master. | J2: 2
A3: 3. Find Final Amount payable (Total Sales + GST). | J3: 2
A4: 4. Find Grand Total of Final Amount. | J4: 2
A5: 5. Count total number of orders using COUNTA. | J5: 2
A6: 6. Find Region-wise total sales using SUMIF. | J6: 2
A7: 7. Use IF to classify Quantity as High (>3) or Low (<=3). | J7: 2
A8: 8. Find the maximum and minimum Final Amount. | J8: 2
A9: 9. Extract month name from Sales_Date. | J9: 2
A10: 10. Sort Sales_Data by Final Amount (Descending). | J10: 2
A11: 11. Use INDEX-MATCH to fetch Product Category. | J11: 2
A12: 12. Calculate average marks of each student. | J12: 2
... A30: 30. Protect the Student_Marks sheet. | J30: 2
J32: =SUM(J1:J30) -> 60

Sheet Answers
A1: 1. Calculate Total Sales for each order (Quantity × Unit_Price). | J1: 2
A3: Order_ID | B3: Region | C3: Salesperson | D3: Product | E3: Quantity | F3: Unit_Price | G3: Sales_Date | H3: Total Sales
A4: 301 | B4: North | C4: Amit | D4: Laptop | E4: 2 | F4: 45000 | G4: 05-01-2025 | H4: =E4*F4 -> 90000
A5: 302 | B5: South | C5: Riya | D5: Mobile | E5: 5 | F5: 15000 | G5: 07-01-2025 | H5: =E5*F5 -> 75000
A6: 303 | B6: East | C6: Kunal | D6: Tablet | E6: 3 | F6: 18000 | G6: 10-01-2025 | H6: =E6*F6 -> 54000
A7: 304 | B7: West | C7: Neha | D7: Laptop | E7: 1 | F7: 45000 | G7: 12-01-2025 | H7: =E7*F7 -> 45000
A8: 305 | B8: North | C8: Amit | D8: Mobile | E8: 4 | F8: 15000 | G8: 15-01-2025 | H8: =E8*F8 -> 60000
A9: 306 | B9: South | C9: Riya | D9: Laptop | E9: 2 | F9: 45000 | G9: 18-01-2025 | H9: =E9*F9 -> 90000
A11: 2. Calculate GST Amount using VLOOKUP from Product_Master. | J11: 2
A13: Order_ID | B13: Region | C13: Salesperson | D13: Product | E13: Quantity | F13: Unit_Price | G13: Sales_Date | H13: Total Sales | I13: GST % | J13: GST Amount/Unit Price | K13: GST Amount
A14: 301 | B14: North | C14: Amit | D14: Laptop | E14: 2 | F14: 45000 | G14: 05-01-2025 | H14: =E14*F14 -> 90000 | I14: =VLOOKUP(D14,Product_Master!$A$1:$C$4,3,0)/100 -> 0.18 | J14: =F14*I14 -> 8100 | K14: =H14*I14 -> 16200
A15: 302 | B15: South | C15: Riya | D15: Mobile | E15: 5 | F15: 15000 | G15: 07-01-2025 | H15: =E15*F15 -> 75000 | I15: =VLOOKUP(D15,Product_Master!$A$1:$C$4,3,0)/100 -> 0.12 | J15: =F15*I15 -> 1800 | K15: =H15*I15 -> 9000
A16: 303 | B16: East | C16: Kunal | D16: Tablet | E16: 3 | F16: 18000 | G16: 10-01-2025 | H16: =E16*F16 -> 54000 | I16: =VLOOKUP(D16,Product_Master!$A$1:$C$4,3,0)/100 -> 0.12 | J16: =F16*I16 -> 2160 | K16: =H16*I16 -> 6480
A17: 304 | B17: West | C17: Neha | D17: Laptop | E17: 1 | F17: 45000 | G17: 12-01-2025 | H17: =E17*F17 -> 45000 | I17: =VLOOKUP(D17,Product_Master!$A$1:$C$4,3,0)/100 -> 0.18 | J17: =F17*I17 -> 8100 | K17: =H17*I17 -> 8100
A18: 305 | B18: North | C18: Amit | D18: Mobile | E18: 4 | F18: 15000 | G18: 15-01-2025 | H18: =E18*F18 -> 60000 | I18: =VLOOKUP(D18,Product_Master!$A$1:$C$4,3,0)/100 -> 0.12 | J18: =F18*I18 -> 1800 | K18: =H18*I18 -> 7200
A19: 306 | B19: South | C19: Riya | D19: Laptop | E19: 2 | F19: 45000 | G19: 18-01-2025 | H19: =E19*F19 -> 90000 | I19: =VLOOKUP(D19,Product_Master!$A$1:$C$4,3,0)/100 -> 0.18 | J19: =F19*I19 -> 8100 | K19: =H19*I19 -> 16200
A21: 3. Find Final Amount payable (Total Sales + GST). | J21: 2
A23: Order_ID | B23: Region | C23: Salesperson | D23: Product | E23: Quantity | F23: Unit_Price | G23: Sales_Date | H23: Total Sales | I23: GST Amount | J23: GST Amount | K23: Total Sales
A24: 301 | B24: North | C24: Amit | D24: Laptop | E24: 2 | F24: 45000 | G24: 05-01-2025 | H24: =E24*F24 -> 90000 | I24: =VLOOKUP(D24,Product_Master!$A$1:$C$4,3,0)/100 -> 0.18 | J24: 16200 | K24: =H24+J24 -> 106200
A25: 302 | B25: South | C25: Riya | D25: Mobile | E25: 5 | F25: 15000 | G25: 07-01-2025 | H25: =E25*F25 -> 75000 | I25: =VLOOKUP(D25,Product_Master!$A$1:$C$4,3,0)/100 -> 0.12 | J25: 9000 | K25: =H25+J25 -> 84000
A26: 303 | B26: East | C26: Kunal | D26: Tablet | E26: 3 | F26: 18000 | G26: 10-01-2025 | H26: =E26*F26 -> 54000 | I26: =VLOOKUP(D26,Product_Master!$A$1:$C$4,3,0)/100 -> 0.12 | J26: 6480 | K26: =H26+J26 -> 60480
A27: 304 | B27: West | C27: Neha | D27: Laptop | E27: 1 | F27: 45000 | G27: 12-01-2025 | H27: =E27*F27 -> 45000 | I27: =VLOOKUP(D27,Product_Master!$A$1:$C$4,3,0)/100 -> 0.18 | J27: 8100 | K27: =H27+J27 -> 53100
A28: 305 | B28: North | C28: Amit | D28: Mobile | E28: 4 | F28: 15000 | G28: 15-01-2025 | H28: =E28*F28 -> 60000 | I28: =VLOOKUP(D28,Product_Master!$A$1:$C$4,3,0)/100 -> 0.12 | J28: 7200 | K28: =H28+J28 -> 67200
A29: 306 | B29: South | C29: Riya | D29: Laptop | E29: 2 | F29: 45000 | G29: 18-01-2025 | H29: =E29*F29 -> 90000 | I29: =VLOOKUP(D29,Product_Master!$A$1:$C$4,3,0)/100 -> 0.18 | J29: 16200 | K29: =H29+J29 -> 106200
A31: 4. Find Grand Total of Final Amount. | J31: 2
A33: Order_ID | B33: Region | C33: Salesperson | D33: Product | E33: Quantity | F33: Unit_Price | G33: Sales_Date | H33: Total Sales | I33: GST Amount | J33: GST Amount | K33: Total Sales
A34: 301 | B34: North | C34: Amit | D34: Laptop | E34: 2 | F34: 45000 | G34: 05-01-2025 | H34: =E34*F34 -> 90000 | I34: =VLOOKUP(D34,Product_Master!$A$1:$C$4,3,0)/100 -> 0.18 | J34: 16200 | K34: =H34+J34 -> 106200
A35: 302 | B35: South | C35: Riya | D35: Mobile | E35: 5 | F35: 15000 | G35: 07-01-2025 | H35: =E35*F35 -> 75000 | I35: =VLOOKUP(D35,Product_Master!$A$1:$C$4,3,0)/100 -> 0.12 | J35: 9000 | K35: =H35+J35 -> 84000
A36: 303 | B36: East | C36: Kunal | D36: Tablet | E36: 3 | F36: 18000 | G36: 10-01-2025 | H36: =E36*F36 -> 54000 | I36: =VLOOKUP(D36,Product_Master!$A$1:$C$4,3,0)/100 -> 0.12 | J36: 6480 | K36: =H36+J36 -> 60480
A37: 304 | B37: West | C37: Neha | D37: Laptop | E37: 1 | F37: 45000 | G37: 12-01-2025 | H37: =E37*F37 -> 45000 | I37: =VLOOKUP(D37,Product_Master!$A$1:$C$4,3,0)/100 -> 0.18 | J37: 8100 | K37: =H37+J37 -> 53100
A38: 305 | B38: North | C38: Amit | D38: Mobile | E38: 4 | F38: 15000 | G38: 15-01-2025 | H38: =E38*F38 -> 60000 | I38: =VLOOKUP(D38,Product_Master!$A$1:$C$4,3,0)/100 -> 0.12 | J38: 7200 | K38: =H38+J38 -> 67200
A39: 306 | B39: South | C39: Riya | D39: Laptop | E39: 2 | F39: 45000 | G39: 18-01-2025 | H39: =E39*F39 -> 90000 | I39: =VLOOKUP(D39,Product_Master!$A$1:$C$4,3,0)/100 -> 0.18 | J39: 16200 | K39: =H39+J39 -> 106200
J40: Final Amount | K40: =SUM(K34:K39) -> 477180
A42: 5. Count total number of orders using COUNTA. | J42: 2
A44: Order_ID | B44: Region | C44: Salesperson | D44: Product | E44: Quantity | F44: Unit_Price | G44: Sales_Date | H44: Total Sales
A45: 301 | B45: North | C45: Amit | D45: Laptop | E45: 2 | F45: 45000 | G45: 05-01-2025 | H45: =E45*F45 -> 90000
A46: 302 | B46: South | C46: Riya | D46: Mobile | E46: 5 | F46: 15000 | G46: 07-01-2025 | H46: =E46*F46 -> 75000
A47: 303 | B47: East | C47: Kunal | D47: Tablet | E47: 3 | F47: 18000 | G47: 10-01-2025 | H47: =E47*F47 -> 54000
A48: 304 | B48: West | C48: Neha | D48: Laptop | E48: 1 | F48: 45000 | G48: 12-01-2025 | H48: =E48*F48 -> 45000
A49: 305 | B49: North | C49: Amit | D49: Mobile | E49: 4 | F49: 15000 | G49: 15-01-2025 | H49: =E49*F49 -> 60000
...
